### `try...catch()` 后端用来处理异常的工具

#### 基本语法

```js
console.log(111);
try {
    // 这里书写 可能 出现异常的代码（尤其是运行时异常）
}
// 如果try中没有出现异常，不会走catch，会跳过catch继续执行 
catch (error) {
    // 要对出现异常的代码执行什么操作
};
console.log(222);
```

#### 案例

```js
console.logggg(1);
// 出错
console.log(2);
// 2不会被打印
```

解决：

```js
try {
    console.logggg(1);
    // 出错
} catch (error) {
    // 处理错误
    console.log(error);
}
// 下面的代码还可以继续执行
console.log(2);
// 2会被继续打印


/* 案例二 */ 
try {
    console.log(1);  // 打印 1 
    console.logggg(2); // 出错
    console.log(3); // 不执行
} catch (error) {
    console.log(error); // 打印错误
}
console.log(4);  // 执行
```



### `throw` 

一般都是用在`try..catch`这个结构中

#### 作用：

中断后面所有语句的执行，包括错误，但是它前面的语句都会正常执行

用于中断代码，调试代码

```js
// try 中尝试错误并用throw抛出
try
{
    if (x == 0)
        throw "x equals zero";
    else
        throw "x does not equal zero";
}
// catch 中捕获并处理
catch(e)
{
    if (e == "x equals zero")
        return(e + " handled locally.");
}


/* 案例二 */
try {
    console.log(1);
    throw ('这里有错');
    console.log(2);
} catch (error) {
    console.log('catch到' + error);
}
console.log(3);
// 1
// catch到这里有错
// 2
```



